<?xml version="1.0" encoding="utf-8"?>
<!-- This URDF was automatically created by SolidWorks to URDF Exporter! Originally created by Stephen Brawner (brawner@gmail.com) 
     Commit Version: 1.6.0-4-g7f85cfe  Build Version: 1.6.7995.38578
     For more information, please see http://wiki.ros.org/sw_urdf_exporter -->
<robot
  name="right">
  <link
    name="base_link">
    <inertial>
      <origin
        xyz="-0.0094603 -0.088524 0.0020382"
        rpy="0 0 0" />
      <mass
        value="0.37668" />
      <inertia
        ixx="0.00026243"
        ixy="-4.7759E-06"
        ixz="-3.6528E-06"
        iyy="0.00031103"
        iyz="1.2051E-05"
        izz="0.00042537" />
    </inertial>
    <visual>
      <origin
        xyz="0 0 0"
        rpy="0 0 0" />
      <geometry>
        <mesh
          filename="package://lz_gripper_rviz/meshes/base_link.STL" />
      </geometry>
      <material
        name="">
        <color
          rgba="0.89804 0.92157 0.92941 1" />
      </material>
    </visual>
    <collision>
      <origin
        xyz="0 0 0"
        rpy="0 0 0" />
      <geometry>
        <mesh
          filename="package://lz_gripper_rviz/meshes/base_link.STL" />
      </geometry>
    </collision>
  </link>
  <link
    name="thumb_link1">
    <inertial>
      <origin
        xyz="-0.00017965 6.8304E-06 0.018159"
        rpy="0 0 0" />
      <mass
        value="0.0099033" />
      <inertia
        ixx="6.2516E-07"
        ixy="-5.4183E-09"
        ixz="6.2081E-08"
        iyy="1.0583E-06"
        iyz="3.9831E-09"
        izz="6.1988E-07" />
    </inertial>
    <visual>
      <origin
        xyz="0 0 0"
        rpy="0 0 0" />
      <geometry>
        <mesh
          filename="package://lz_gripper_rviz/meshes/thumb_link1.STL" />
      </geometry>
      <material
        name="">
        <color
          rgba="0.89804 0.92157 0.92941 1" />
      </material>
    </visual>
    <collision>
      <origin
        xyz="0 0 0"
        rpy="0 0 0" />
      <geometry>
        <mesh
          filename="package://lz_gripper_rviz/meshes/thumb_link1.STL" />
      </geometry>
    </collision>
  </link>
  <joint
    name="thumb_joint1"
    type="revolute">
    <origin
      xyz="0.023 -0.0245 -0.04835"
      rpy="3.1416 0 -3.1416" />
    <parent
      link="base_link" />
    <child
      link="thumb_link1" />
    <axis
      xyz="0 0 1" />
    <limit
      lower="0"
      upper="2.14"
      effort="100"
      velocity="1" />
  </joint>
  <link
    name="thumb_link2">
    <inertial>
      <origin
        xyz="-0.020501 0.0067015 -0.0064038"
        rpy="0 0 0" />
      <mass
        value="0.014226" />
      <inertia
        ixx="6.8248E-07"
        ixy="6.3443E-07"
        ixz="4.2546E-10"
        iyy="2.4065E-06"
        iyz="5.4467E-10"
        izz="2.8832E-06" />
    </inertial>
    <visual>
      <origin
        xyz="0 0 0"
        rpy="0 0 0" />
      <geometry>
        <mesh
          filename="package://lz_gripper_rviz/meshes/thumb_link2.STL" />
      </geometry>
      <material
        name="">
        <color
          rgba="0.89804 0.92157 0.92941 1" />
      </material>
    </visual>
    <collision>
      <origin
        xyz="0 0 0"
        rpy="0 0 0" />
      <geometry>
        <mesh
          filename="package://lz_gripper_rviz/meshes/thumb_link2.STL" />
      </geometry>
    </collision>
  </link>
  <joint
    name="thumb_joint2"
    type="revolute">
    <origin
      xyz="-0.0088613 0.0060912 0.01565"
      rpy="-1.5708 0 0.018038" />
    <parent
      link="thumb_link1" />
    <child
      link="thumb_link2" />
    <axis
      xyz="0 0 -1" />
    <limit
      lower="0"
      upper="0.35"
      effort="100"
      velocity="1" />
  </joint>
  <link
    name="thumb_link3">
    <inertial>
      <origin
        xyz="-0.0196680927954652 -0.0005819719341843 0.00789994316554879"
        rpy="0 0 0" />
      <mass
        value="0.00784968038272673" />
      <inertia
        ixx="2.81075874673003E-07"
        ixy="1.75602810939405E-08"
        ixz="-8.67190758135838E-12"
        iyy="1.53707272171153E-06"
        iyz="8.14073757746129E-13"
        izz="1.36361714001957E-06" />
    </inertial>
    <visual>
      <origin
        xyz="0 0 0"
        rpy="0 0 0" />
      <geometry>
        <mesh
          filename="package://lz_gripper_rviz/meshes/thumb_link3.STL" />
      </geometry>
      <material
        name="">
        <color
          rgba="0.898039215686275 0.92156862745098 0.929411764705882 1" />
      </material>
    </visual>
    <collision>
      <origin
        xyz="0 0 0"
        rpy="0 0 0" />
      <geometry>
        <mesh
          filename="package://lz_gripper_rviz/meshes/thumb_link3.STL" />
      </geometry>
    </collision>
  </link>
  <joint
    name="thumb_joint3"
    type="revolute">
    <origin
      xyz="-0.042286 0.015391 -0.01415"
      rpy="0 0 -0.34907" />
    <parent
      link="thumb_link2" />
    <child
      link="thumb_link3" />
    <axis
      xyz="0 0 -1" />
    <limit
      lower="0"
      upper="1.57"
      effort="100"
      velocity="1" />
  </joint>
  <link
    name="index_link1">
    <inertial>
      <origin
        xyz="-0.0215644823473152 0.000393824084923317 -0.00874621135392779"
        rpy="0 0 0" />
      <mass
        value="0.0142262329639115" />
      <inertia
        ixx="4.74796817289846E-07"
        ixy="3.63252054246068E-08"
        ixz="-2.22673309099261E-10"
        iyy="2.61422515976766E-06"
        iyz="6.54075662009712E-10"
        izz="2.88324671047069E-06" />
    </inertial>
    <visual>
      <origin
        xyz="0 0 0"
        rpy="0 0 0" />
      <geometry>
        <mesh
          filename="package://lz_gripper_rviz/meshes/index_link1.STL" />
      </geometry>
      <material
        name="">
        <color
          rgba="0.898039215686275 0.92156862745098 0.929411764705882 1" />
      </material>
    </visual>
    <collision>
      <origin
        xyz="0 0 0"
        rpy="0 0 0" />
      <geometry>
        <mesh
          filename="package://lz_gripper_rviz/meshes/index_link1.STL" />
      </geometry>
    </collision>
  </link>
  <joint
    name="index_joint1"
    type="revolute">
    <origin
      xyz="0.031418 0 -0.0053197"
      rpy="3.1416 1.5359 3.1416" />
    <parent
      link="base_link" />
    <child
      link="index_link1" />
    <axis
      xyz="0 0 1" />
    <limit
      lower="0"
      upper="1.57"
      effort="100"
      velocity="1" />
  </joint>
  <link
    name="index_link2">
    <inertial>
      <origin
        xyz="-0.019676 -6.2395E-05 -0.0079"
        rpy="0 0 0" />
      <mass
        value="0.0078496" />
      <inertia
        ixx="2.8357E-07"
        ixy="-5.8625E-08"
        ixz="5.9491E-12"
        iyy="1.5346E-06"
        iyz="6.753E-14"
        izz="1.3636E-06" />
    </inertial>
    <visual>
      <origin
        xyz="0 0 0"
        rpy="0 0 0" />
      <geometry>
        <mesh
          filename="package://lz_gripper_rviz/meshes/index_link2.STL" />
      </geometry>
      <material
        name="">
        <color
          rgba="0.89804 0.92157 0.92941 1" />
      </material>
    </visual>
    <collision>
      <origin
        xyz="0 0 0"
        rpy="0 0 0" />
      <geometry>
        <mesh
          filename="package://lz_gripper_rviz/meshes/index_link2.STL" />
      </geometry>
    </collision>
  </link>
  <joint
    name="index_joint2"
    type="revolute">
    <origin
      xyz="-0.044995 -0.00066876 -0.001"
      rpy="0 0 0" />
    <parent
      link="index_link1" />
    <child
      link="index_link2" />
    <axis
      xyz="0 0 1" />
    <limit
      lower="0"
      upper="1.57"
      effort="100"
      velocity="1" />
  </joint>
  <link
    name="middle_link1">
    <inertial>
      <origin
        xyz="-0.0215562506031045 0.000714276767812562 -0.00874619886653837"
        rpy="0 0 0" />
      <mass
        value="0.0142262397904175" />
      <inertia
        ixx="4.76348437272591E-07"
        ixy="6.81026341965301E-08"
        ixz="-2.11739551609207E-10"
        iyy="2.61267178108045E-06"
        iyz="6.56674816237693E-10"
        izz="2.88324556739897E-06" />
    </inertial>
    <visual>
      <origin
        xyz="0 0 0"
        rpy="0 0 0" />
      <geometry>
        <mesh
          filename="package://lz_gripper_rviz/meshes/middle_link1.STL" />
      </geometry>
      <material
        name="">
        <color
          rgba="0.898039215686275 0.92156862745098 0.929411764705882 1" />
      </material>
    </visual>
    <collision>
      <origin
        xyz="0 0 0"
        rpy="0 0 0" />
      <geometry>
        <mesh
          filename="package://lz_gripper_rviz/meshes/middle_link1.STL" />
      </geometry>
    </collision>
  </link>
  <joint
    name="middle_joint1"
    type="revolute">
    <origin
      xyz="0.0089 0 0"
      rpy="0 1.5708 0" />
    <parent
      link="base_link" />
    <child
      link="middle_link1" />
    <axis
      xyz="0 0 1" />
    <limit
      lower="0"
      upper="1.57"
      effort="100"
      velocity="1" />
  </joint>
  <link
    name="middle_link2">
    <inertial>
      <origin
        xyz="-0.0196680995356125 0.000581962591357868 -0.00789993606542237"
        rpy="0 0 0" />
      <mass
        value="0.00784967565480307" />
      <inertia
        ixx="2.81075990649539E-07"
        ixy="-1.75598147871464E-08"
        ixz="9.1619521816691E-12"
        iyy="1.53707336727064E-06"
        iyz="9.30781747045291E-13"
        izz="1.36361817821565E-06" />
    </inertial>
    <visual>
      <origin
        xyz="0 0 0"
        rpy="0 0 0" />
      <geometry>
        <mesh
          filename="package://lz_gripper_rviz/meshes/middle_link2.STL" />
      </geometry>
      <material
        name="">
        <color
          rgba="0.898039215686275 0.92156862745098 0.929411764705882 1" />
      </material>
    </visual>
    <collision>
      <origin
        xyz="0 0 0"
        rpy="0 0 0" />
      <geometry>
        <mesh
          filename="package://lz_gripper_rviz/meshes/middle_link2.STL" />
      </geometry>
    </collision>
  </link>
  <joint
    name="middle_joint2"
    type="revolute">
    <origin
      xyz="-0.045 0 -0.001"
      rpy="0 0 1.5708" />
    <parent
      link="middle_link1" />
    <child
      link="middle_link2" />
    <axis
      xyz="0 0 1" />
    <limit
      lower="0"
      upper="1.57"
      effort="100"
      velocity="1" />
  </joint>
  <link
    name="ring_link1">
    <inertial>
      <origin
        xyz="-0.0215562631632659 0.00071427737556939 -0.00874620018386888"
        rpy="0 0 0" />
      <mass
        value="0.0142262435769468" />
      <inertia
        ixx="4.76349000995179E-07"
        ixy="6.81020931307809E-08"
        ixz="-2.12503697751352E-10"
        iyy="2.61267824583491E-06"
        iyz="6.56558908193673E-10"
        izz="2.88325223980858E-06" />
    </inertial>
    <visual>
      <origin
        xyz="0 0 0"
        rpy="0 0 0" />
      <geometry>
        <mesh
          filename="package://lz_gripper_rviz/meshes/ring_link1.STL" />
      </geometry>
      <material
        name="">
        <color
          rgba="0.898039215686275 0.92156862745098 0.929411764705882 1" />
      </material>
    </visual>
    <collision>
      <origin
        xyz="0 0 0"
        rpy="0 0 0" />
      <geometry>
        <mesh
          filename="package://lz_gripper_rviz/meshes/ring_link1.STL" />
      </geometry>
    </collision>
  </link>
  <joint
    name="ring_joint1"
    type="revolute">
    <origin
      xyz="-0.013629 0 -0.0046985"
      rpy="0 1.5359 0" />
    <parent
      link="base_link" />
    <child
      link="ring_link1" />
    <axis
      xyz="0 0 1" />
    <limit
      lower="0"
      upper="1.57"
      effort="100"
      velocity="1" />
  </joint>
  <link
    name="ring_link2">
    <inertial>
      <origin
        xyz="-0.0196679867849359 0.000581976188691607 -0.00789991025971003"
        rpy="0 0 0" />
      <mass
        value="0.00784962520464454" />
      <inertia
        ixx="2.81074318951396E-07"
        ixy="-1.7555732490274E-08"
        ixz="1.27085169733249E-11"
        iyy="1.5370525534456E-06"
        iyz="2.09501544213668E-12"
        izz="1.36359734443304E-06" />
    </inertial>
    <visual>
      <origin
        xyz="0 0 0"
        rpy="0 0 0" />
      <geometry>
        <mesh
          filename="package://lz_gripper_rviz/meshes/ring_link2.STL" />
      </geometry>
      <material
        name="">
        <color
          rgba="0.898039215686275 0.92156862745098 0.929411764705882 1" />
      </material>
    </visual>
    <collision>
      <origin
        xyz="0 0 0"
        rpy="0 0 0" />
      <geometry>
        <mesh
          filename="package://lz_gripper_rviz/meshes/ring_link2.STL" />
      </geometry>
    </collision>
  </link>
  <joint
    name="ring_joint2"
    type="revolute">
    <origin
      xyz="-0.045 0 -0.001"
      rpy="0 0 0" />
    <parent
      link="ring_link1" />
    <child
      link="ring_link2" />
    <axis
      xyz="0 0 1" />
    <limit
      lower="0"
      upper="1.57"
      effort="100"
      velocity="1" />
  </joint>
  <link
    name="little_link1">
    <inertial>
      <origin
        xyz="0 0 0"
        rpy="0 0 0" />
      <mass
        value="0" />
      <inertia
        ixx="0"
        ixy="0"
        ixz="0"
        iyy="0"
        iyz="0"
        izz="0" />
    </inertial>
    <visual>
      <origin
        xyz="0 0 0"
        rpy="0 0 0" />
      <geometry>
        <mesh
          filename="package://lz_gripper_rviz/meshes/little_link1.STL" />
      </geometry>
      <material
        name="">
        <color
          rgba="1 1 1 1" />
      </material>
    </visual>
    <collision>
      <origin
        xyz="0 0 0"
        rpy="0 0 0" />
      <geometry>
        <mesh
          filename="package://lz_gripper_rviz/meshes/little_link1.STL" />
      </geometry>
    </collision>
  </link>
  <joint
    name="little_joint1"
    type="revolute">
    <origin
      xyz="-0.036007 0 -0.0094157"
      rpy="0 1.501 0" />
    <parent
      link="base_link" />
    <child
      link="little_link1" />
    <axis
      xyz="0 0 1" />
    <limit
      lower="0"
      upper="1.57"
      effort="100"
      velocity="1" />
  </joint>
  <link
    name="little_link2">
    <inertial>
      <origin
        xyz="-0.0196680071986052 0.000581972212251745 -0.00789991313401341"
        rpy="0 0 0" />
      <mass
        value="0.00784963356765954" />
      <inertia
        ixx="2.81074629444425E-07"
        ixy="-1.75567896523501E-08"
        ixz="1.20217775074536E-11"
        iyy="1.53705622021842E-06"
        iyz="1.91083841216387E-12"
        izz="1.36360123319282E-06" />
    </inertial>
    <visual>
      <origin
        xyz="0 0 0"
        rpy="0 0 0" />
      <geometry>
        <mesh
          filename="package://lz_gripper_rviz/meshes/little_link2.STL" />
      </geometry>
      <material
        name="">
        <color
          rgba="0.898039215686275 0.92156862745098 0.929411764705882 1" />
      </material>
    </visual>
    <collision>
      <origin
        xyz="0 0 0"
        rpy="0 0 0" />
      <geometry>
        <mesh
          filename="package://lz_gripper_rviz/meshes/little_link2.STL" />
      </geometry>
    </collision>
  </link>
  <joint
    name="little_joint2"
    type="revolute">
    <origin
      xyz="-0.045 0 -0.001"
      rpy="0 0 0" />
    <parent
      link="little_link1" />
    <child
      link="little_link2" />
    <axis
      xyz="0 0 1" />
    <limit
      lower="0"
      upper="1.57"
      effort="100"
      velocity="1" />
  </joint>
</robot>